Workbook
Name Fullskala: 'CRITERIOS DE CALIFICACIÓN'!$B$2:$B$7
Name OLE_LINK1: CUESTIONARIO!#REF!
Name OLE_LINK3: CUESTIONARIO!$A$59
Name OLE_LINK5: CUESTIONARIO!#REF!
Name Score_ISBR1: CUESTIONARIO!$E$2
Name Score_ISBR10: CUESTIONARIO!$E$68
Name Score_ISBR11: CUESTIONARIO!$E$78
Name Score_ISBR12: CUESTIONARIO!$E$84
Name Score_ISBR13: CUESTIONARIO!$E$89
Name Score_ISBR14: CUESTIONARIO!$E$97
Name Score_ISBR15: CUESTIONARIO!$E$102
Name Score_ISBR16: CUESTIONARIO!$E$116
Name Score_ISBR17: CUESTIONARIO!$E$127
Name Score_ISBR18: CUESTIONARIO!$E$131
Name Score_ISBR19: CUESTIONARIO!$E$143
Name Score_ISBR2: CUESTIONARIO!$E$12
Name Score_ISBR3: CUESTIONARIO!$E$22
Name Score_ISBR4: CUESTIONARIO!$E$28
Name Score_ISBR5: CUESTIONARIO!$E$37
Name Score_ISBR6: CUESTIONARIO!$E$44
Name Score_ISBR7: CUESTIONARIO!$E$51
Name Score_ISBR8: CUESTIONARIO!$E$59
Name Score_ISBR9: CUESTIONARIO!$E$64
Name SÍ: CUESTIONARIO!$C$3
Name Title_ISBR1: CUESTIONARIO!$A$2
Name Title_ISBR10: CUESTIONARIO!$A$68
Name Title_ISBR11: CUESTIONARIO!$A$78
Name Title_ISBR12: CUESTIONARIO!$A$84
Name Title_ISBR13: CUESTIONARIO!$A$89
Name Title_ISBR14: CUESTIONARIO!$A$97
Name Title_ISBR15: CUESTIONARIO!$A$102
Name Title_ISBR16: CUESTIONARIO!$A$116
Name Title_ISBR17: CUESTIONARIO!$A$127
Name Title_ISBR18: CUESTIONARIO!$A$131
Name Title_ISBR19: CUESTIONARIO!$A$143
Name Title_ISBR2: CUESTIONARIO!$A$12
Name Title_ISBR3: CUESTIONARIO!$A$22
Name Title_ISBR4: CUESTIONARIO!$A$28
Name Title_ISBR5: CUESTIONARIO!$A$37
Name Title_ISBR6: CUESTIONARIO!$A$44
Name Title_ISBR7: CUESTIONARIO!$A$51
Name Title_ISBR8: CUESTIONARIO!$A$59
Name Title_ISBR9: CUESTIONARIO!$A$64
Name yesno: 'CRITERIOS DE CALIFICACIÓN'!$B$10:$B$11

Sheet INTRODUCCIÓN
B1: Una evaluación técnica de 19 aspectos clave
B2: Esta es una herramienta de autoevaluación para verificar el grado de cumplimiento de una empresa con los requisitos básicos de seguridad de la información. La herramienta está destinada a ayudar a las empresas a evaluar el nivel de seguridad de sus sistemas informáticos y de control de procesos, seguridad y soporte. No está destinada a ser utilizada para realizar informes a terceros como criterio de cumplimiento, este auto diagnóstico está diseñado únicamente para uso interno. La utilización de esta herramienta depende totalmente de la empresa y siempre considerando que es para los usos legales que a ella convengan sin involucrar legalmente, administrativamente, asociativamente o de cualquier otra índole a Innevo ya que la única intención es que sirva como punto de inicio a cualquier organización que desea conocer de forma general el grado de exposición que tiene en su sistema de gestión de seguridad de la información.
A3: Obtén más recursos y conoce nuestros servicios en innevo.com
A5: Cómo usar este recurso
A6: 1. Guarda una copia en tu dispositivo o almacenamiento en la nube
A7: 2. Abre el documento.
A8: 3. Si tus configuraciones de seguridad lo abren en "VISTA PROTEGIDA", asegúrate de Habilitar la edición.
A9: 4. Siguiendo estos pasos, podrás hacer uso de la hoja CUESTIONARIO que calculará automáticamente el puntaje de tu empresa según tus respuestas.
A10: 5. Revisa la hoja INTERPRETACIÓN DEL DIAGNÓSTICO para conocer los resultados.

Sheet CUESTIONARIO
A1: # | B1: Concepto | C1: Calificación | D1: Notas o comentarios | E1: Puntaje obtenido
A2: 1.- Política de seguridad de la información. | E2: =AVERAGE(E3:E11) -> #DIV/0!
A3: 1-1 | B3: ¿Tiene la empresa un documento de política de seguridad de la información desarrollado específicamente para ella? | E3: =IF(C3="","",(VLOOKUP(C3,'CRITERIOS DE CALIFICACIÓN'!$B$2:$C$11,2,FALSE)))
A4: 1-2 | B4: Si la respuesta a la pregunta anterior fue NO, conteste: ¿Tiene la empresa políticas de seguridad de la información no documentadas pero incorporadas en sus procesos? | E4: =IF(C4="","",(VLOOKUP(C4,'CRITERIOS DE CALIFICACIÓN'!$B$2:$C$11,2,FALSE)))
A5: 1-3 | B5: Si la respuesta a la pregunta 1-1 fue SÍ, responda ¿La política de seguridad de la información ha sido firmada por la alta dirección?. | E5: =IF(C5="","",(VLOOKUP(C5,'CRITERIOS DE CALIFICACIÓN'!$B$2:$C$11,2,FALSE)))
A6: 1-4 | B6: ¿No ha pasada más de un año desde que se redactó o revisó la política de seguridad de la información? | E6: =IF(C6="","",(VLOOKUP(C6,'CRITERIOS DE CALIFICACIÓN'!$B$2:$C$11,2,FALSE)))
A7: 1-5 | B7: ¿En qué medida se aplica la política de seguridad de la información en todos los entornos de producción de la empresa? | E7: =IF(C7="","",(VLOOKUP(C7,'CRITERIOS DE CALIFICACIÓN'!$B$2:$C$11,2,FALSE)))
A8: 1-6 | B8: ¿En qué medida la alta dirección es activa en la promoción y aplicación de la política de seguridad de la información? | E8: =IF(C8="","",(VLOOKUP(C8,'CRITERIOS DE CALIFICACIÓN'!$B$2:$C$11,2,FALSE)))
A9: 1-7 | B9: ¿En qué medida tu personal y proveedores están informados y familiarizados con la política de seguridad de la información? | E9: =IF(C9="","",(VLOOKUP(C9,'CRITERIOS DE CALIFICACIÓN'!$B$2:$C$11,2,FALSE)))
A10: 1-8 | B10: ¿En qué medida todo el personal y proveedores cumplen con la política de seguridad de la información? | E10: =IF(C10="","",(VLOOKUP(C10,'CRITERIOS DE CALIFICACIÓN'!$B$2:$C$11,2,FALSE)))
A11: 1-9 | B11: ¿En qué medida la política de seguridad de la información cubre las necesidades de seguridad de información de tus clientes y reglamentos que le apliquen? | E11: =IF(C11="","",(VLOOKUP(C11,'CRITERIOS DE CALIFICACIÓN'!$B$2:$C$11,2,FALSE)))
A12: 2. - Proceso de gestión de riesgos de seguridad de la información para los sistemas y redes. | E12: =AVERAGE(E13:E21) -> #DIV/0!
A13: 2-1 | B13: ¿Tiene la empresa requisitos documentados para realizar evaluaciones de riesgos periódicas de todos los sistemas informáticos críticos? | E13: =IF(C13="","",(VLOOKUP(C13,'CRITERIOS DE CALIFICACIÓN'!$B$2:$C$11,2,FALSE)))
A14: 2-2 | B14: ¿Tiene la empresa un marco o metodología documentada para la evaluación de riesgos que se pueda utilizar para la seguridad de la información? | E14: =IF(C14="","",(VLOOKUP(C14,'CRITERIOS DE CALIFICACIÓN'!$B$2:$C$11,2,FALSE)))
A15: 2-3 | B15: ¿En qué medida se han realizado evaluaciones de riesgos para la seguridad de la información para todos los sistemas críticos durante el año pasado? | E15: =IF(C15="","",(VLOOKUP(C15,'CRITERIOS DE CALIFICACIÓN'!$B$2:$C$11,2,FALSE)))
A16: 2-4 | B16: ¿En qué medida ha aprobado la dirección general el riesgo residual una vez mitigados los riesgos pre-existentes y el plan de implementación de las medidas y controles de seguridad propuestos? | E16: =IF(C16="","",(VLOOKUP(C16,'CRITERIOS DE CALIFICACIÓN'!$B$2:$C$11,2,FALSE)))
A17: 2-5 | B17: ¿En qué medida se enfrentan inmediatamente los nuevos riesgos graves de seguridad de la información? | E17: =IF(C17="","",(VLOOKUP(C17,'CRITERIOS DE CALIFICACIÓN'!$B$2:$C$11,2,FALSE)))
A18: 2-6 | B18: ¿En qué medida se dispone de documentación, estructura y presentación de informes sobre los riesgos identificados? | E18: =IF(C18="","",(VLOOKUP(C18,'CRITERIOS DE CALIFICACIÓN'!$B$2:$C$11,2,FALSE)))
A19: 2-7 | B19: ¿En qué medida se registran todos los nuevos riesgos de seguridad de la información? | E19: =IF(C19="","",(VLOOKUP(C19,'CRITERIOS DE CALIFICACIÓN'!$B$2:$C$11,2,FALSE)))
A20: 2-8 | B20: ¿En qué medida se hace un seguimiento de todos los riesgos registrados y se responde en un plazo razonable? | E20: =IF(C20="","",(VLOOKUP(C20,'CRITERIOS DE CALIFICACIÓN'!$B$2:$C$11,2,FALSE)))
A21: 2-9 | B21: ¿Existe un plan de mitigación de riesgos con actividades de mitigación estructuradas en actividades proactivas y reactivas, basadas en medidas preventivas, de detección o correctivas para garantizar la reducción de riesgos que involucren tanto la probabilidad como el impacto de incidentes y violaciones de seguridad? | E21: =IF(C21="","",(VLOOKUP(C21,'CRITERIOS DE CALIFICACIÓN'!$B$2:$C$11,2,FALSE)))
A22: 3. - Los sistemas informáticos y de resguardo de información no digital deben tener propietarios designados y de los datos correspondientes. | E22: =AVERAGE(E23:E27) -> #DIV/0!
A23: 3-1 | B23: ¿Existen requisitos internos para designar propietarios de sistemas y/o información para sistemas críticos? | E23: =IF(C23="","",(VLOOKUP(C23,'CRITERIOS DE CALIFICACIÓN'!$B$2:$C$11,2,FALSE)))
A24: 3-2 | B24: ¿En qué medida se designan realmente propietarios de sistemas/información para todos los sistemas críticos ? | E24: =IF(C24="","",(VLOOKUP(C24,'CRITERIOS DE CALIFICACIÓN'!$B$2:$C$11,2,FALSE)))
A25: 3-3 | B25: ¿Tiene la empresa una visión general completa, actualizada y documentada (lista o base de datos) del personal designado como propietario del sistema/información? | E25: =IF(C25="","",(VLOOKUP(C25,'CRITERIOS DE CALIFICACIÓN'!$B$2:$C$11,2,FALSE)))
A26: 3-4 | B26: ¿Tiene la empresa documentación que describa la autoridad y las responsabilidades del rol del propietario del sistema/información? | E26: =IF(C26="","",(VLOOKUP(C26,'CRITERIOS DE CALIFICACIÓN'!$B$2:$C$11,2,FALSE)))
A27: 3-5 | B27: ¿Se ha establecido la división de las funciones y responsabilidades de seguridad entre los propietarios de sistemas/información y las partes interesadas de terceros (por ejemplo, proveedores, clientes y socios) para cada sistema, equipo de dómputo o componente de infraestructura de TI? | E27: =IF(C27="","",(VLOOKUP(C27,'CRITERIOS DE CALIFICACIÓN'!$B$2:$C$11,2,FALSE)))
A28: 4. - La infraestructura informática debe tener redes segmentadas y todas las rutas de comunicación deben ser controladas y auditadas. | E28: =AVERAGE(E29:E36) -> #DIV/0!
A29: 4-1 | B29: ¿Tiene la empresa requisitos documentados para segmentar las redes de dominio de las del dominio de oficina? | E29: =IF(C29="","",(VLOOKUP(C29,'CRITERIOS DE CALIFICACIÓN'!$B$2:$C$11,2,FALSE)))
A30: 4-2 | B30: ¿En qué medida las redes de dominio de están realmente segmentadas de las del dominio de la oficina (por ejemplo, mediante la instalación de firewalls estrechamente configurados entre ellas)? | E30: =IF(C30="","",(VLOOKUP(C30,'CRITERIOS DE CALIFICACIÓN'!$B$2:$C$11,2,FALSE)))
A31: 4-3 | B31: ¿En qué medida las redes del dominio de las TIC del PCSS están segmentadas entre sí (es decir, los sistemas que no tienen una necesidad funcional u operativa de estar en la misma red están segmentados entre sí)? | E31: =IF(C31="","",(VLOOKUP(C31,'CRITERIOS DE CALIFICACIÓN'!$B$2:$C$11,2,FALSE)))
A32: 4-4 | B32: ¿En qué medida la comunicación de datos entre los diferentes segmentos de red en el dominio está controlada por interfaces (por ejemplo, firewalls, enrutadores de filtrado)? | E32: =IF(C32="","",(VLOOKUP(C32,'CRITERIOS DE CALIFICACIÓN'!$B$2:$C$11,2,FALSE)))
A33: 4-5 | B33: ¿Hasta qué punto toda la comunicación de datos externos entre las redes y los proveedores pasa a través de interfaces controladas (por ejemplo, firewalls, servidores de terminales)? | E33: =IF(C33="","",(VLOOKUP(C33,'CRITERIOS DE CALIFICACIÓN'!$B$2:$C$11,2,FALSE)))
A34: 4-6 | B34: ¿Se revisan regularmente las reglas de firewall para garantizar que solo se configuren las reglas necesarias? | E34: =IF(C34="","",(VLOOKUP(C34,'CRITERIOS DE CALIFICACIÓN'!$B$2:$C$11,2,FALSE)))
A35: 4-7 | B35: ¿Se registran y supervisan los cortafuegos? | E35: =IF(C35="","",(VLOOKUP(C35,'CRITERIOS DE CALIFICACIÓN'!$B$2:$C$11,2,FALSE)))
A36: 4-8 | B36: ¿En qué medida la solución de gestión de cortafuegos está protegida contra el acceso no autorizado (es decir, mediante la autenticación de dos factores)? | E36: =IF(C36="","",(VLOOKUP(C36,'CRITERIOS DE CALIFICACIÓN'!$B$2:$C$11,2,FALSE)))
A37: 5. - Los usuarios de los sistemas deben recibir capacitación en la conciencia de la seguridad de la información y el uso seguro de los sistemas de TI de acuerdo con las políticas y procesos establecidos. | E37: =AVERAGE(E38:E43) -> #DIV/0!
A38: 5-1 | B38: ¿En qué medida se han establecido requisitos documentados para proporcionar capacitación actualizada en seguridad de la información para todo el personal? | E38: =IF(C38="","",(VLOOKUP(C38,'CRITERIOS DE CALIFICACIÓN'!$B$2:$C$11,2,FALSE)))
A39: 5-2 | B39: ¿En qué medida se está capacitando en seguridad de la información al personal recién contratado? | E39: =IF(C39="","",(VLOOKUP(C39,'CRITERIOS DE CALIFICACIÓN'!$B$2:$C$11,2,FALSE)))
A40: 5-3 | B40: ¿En qué medida también está disponible para los proveedores una capacitación actualizada sobre seguridad de la información? | E40: =IF(C40="","",(VLOOKUP(C40,'CRITERIOS DE CALIFICACIÓN'!$B$2:$C$11,2,FALSE)))
...

Sheet INTERPRETACIÓN DEL DIAGNÓSTICO
A1: Empresa:
A2: Fecha de evaluación:
A3: Participantes en la evaluación
A4: Concepto evaluado e interpretación | D4: Puntaje obtenido
A5: =Title_ISBR1 -> 1.- Política de seguridad de la información. | D5: =Score_ISBR1 -> #DIV/0!
A6: 3 < PO ≤ 4 | B6: Su empresa tiene lo necesario para considerar que su política de seguridad de la información existe y es eficaz.
A7: 2 < PO ≤ 3 | B7: Su empresa tiene una aceptable política se seguridad de la información pero requiere actualización anual y auditorías de cumplimiento para estar seguro de que se cumple.
A8: 1 < PO ≤ 2 | B8: Su empresa adolece de una eficaz política de seguridad y es necesario reforzar la capacitación del personal y concientización de cumplimiento.
A9: 0 < PO ≤ 1 | B9: No tiene una política de seguridad de la información y requiere algún proceso básico que ejecute su personal para salir del grado de exposición que su empresa tiene.
A10: =Title_ISBR2 -> 2. - Proceso de gestión de riesgos de seguridad de la información para los sistemas y redes. | D10: =Score_ISBR2 -> #DIV/0!
A11: 3 < PO ≤ 4 | B11: Su empresa tiene un buen sistema de administración de riesgos de seguridad, está bajo la denominación de riesgos bajo control.
A12: 2 < PO ≤ 3 | B12: Aunque la administración de riesgos tiene un nivel aceptable todavía tiene vulnerabilidades que debe revisar. Es necesario que realice un análisis exhaustivo de vulnerabilidades en gente, procesos y tecnología para asegurar una denominación de riesgos bajo control.
A13: 1 < PO ≤ 2 | B13: Su administración de riesgos de seguridad de la información es deficiente y tiene expuesta a su organización. Es necesario que lo antes posible realice una revisión exhaustiva de vulnerabilidades.
A14: 0 < PO ≤ 1 | B14: La información de su empresa está expuesta. Es urgente que realice una análisis exhaustivo de vulnerabilidades.
A15: =Title_ISBR3 -> 3. - Los sistemas informáticos y de resguardo de información no digital deben tener propietarios designados y de los datos correspondientes. | D15: =Score_ISBR3 -> #DIV/0!
A16: 3 < PO ≤ 4 | B16: Su empresa tiene un buen sistema de administración de funciones, responsabilidades y autoridad de uso de la información para el personal.
A17: 2 < PO ≤ 3 | B17: Aunque su administración de funciones de uso de información es bueno, es necesario que revise la parte de responsabilidades y autoridad de uso de la información en su personal.
A18: 1 < PO ≤ 2 | B18: Su sistema de administración de funciones, responsabilidades y autoridad de uso de la información es muy deficiente. Es importante que revise este tema lo antes posible.
A19: 0 < PO ≤ 1 | B19: Su sistema de administración de funciones, responsabilidades y autoridad de uso de la información es inexistente. Esta situación tiene expuesta a su empresa. Es urgente que cuanto antes se atienda esta condición.
A20: =Title_ISBR4 -> 4. - La infraestructura informática debe tener redes segmentadas y todas las rutas de comunicación deben ser controladas y auditadas. | D20: =Score_ISBR4 -> #DIV/0!
A21: 3 < PO ≤ 4 | B21: Su infraestructura está controlada y se encuentra en la condición de vulnerabilidades bajo control.
A22: 2 < PO ≤ 3 | B22: Aunque su infraestructura es buena requiere de revisiones de configuración de políticas de seguridad en equipos de comunicación y redes para lograr la condición de vulnerabilidades bajo control.
A23: 1 < PO ≤ 2 | B23: La infraestructura de su empresa apenas cumple con los requisitos básicos para controlar las vulneabilidades más importantes. Es nedcesio que cuanto antes desarrolle un plan de análisis de vulnerabilidades en equipos de comunicación y redes. Su condición es de vulnerabilidades latentes.
A24: 0 < PO ≤ 1 | B24: La infraestructura de su empresa está expuesta. Su condición es de vulnerabilidades sin control.
A25: =Title_ISBR5 -> 5. - Los usuarios de los sistemas deben recibir capacitación en la conciencia de la seguridad de la información y el uso seguro de los sistemas de TI de acuerdo con las políticas y procesos establecidos. | D25: =Score_ISBR5 -> #DIV/0!
A26: 3 < PO ≤ 4 | B26: Su personal está consciente y ejecuta los procesos de seguridad de la información. Su empresa tiene la condición de cultura de seguridad de la información bajo control.
A27: 2 < PO ≤ 3 | B27: Su personal aunque está consciente de la seguridad de la información tiene fallas debido a capacitación deficiente. Es importante que cuanto antes ejecute un nuevo plan de concientización y capacitación de seguridad de la información para su personal. Su empresa tiene la condición de cultura de seguirdad de la información básica.
A28: 1 < PO ≤ 2 | B28: Su personal no tiene consciencia y comportamientos adecuados para ejecutar una eficiente política de seguridad de la información. Su empresa tiene la condición de cultura de seguridad de la información ineficiente.
A29: 0 < PO ≤ 1 | B29: Los usos y construmbres de su personal exponen a su empresa. Es urgente que implemente un plan de concientización, capacitación y supervisión de política de seguridad de la información. Su empresa tiene la condición de cultura de seguridad de la información inexistente.
A30: =Title_ISBR6 -> 6. - Los sistemas informáticos sólo se utilizarán para los fines designados. | D30: =Score_ISBR6 -> #DIV/0!
A31: 3 < PO ≤ 4 | B31: Su empresa tiene un control eficaz sobre la utilización institucional de sus equipos informáticos. La condición de su empresa es infraestructura controlada.
A32: 2 < PO ≤ 3 | B32: Su empresa tiene un control eficaz sobre la utilización institucional de sus equipos informáticos de escritorio pero deficiente en móviles o externos a la red corporativa. La condición de su empresa es infraestructura parcialmente controlada.
A33: 1 < PO ≤ 2 | B33: Su empresa tiene vulnerabiliades latentes debidas a una deficiente administración y control de su infraestructura informática. La condición de su empresa es infraestructura bajo riesgo.
A34: 0 < PO ≤ 1 | B34: Su empresa tiene vulnerabilidades graves y expuestas. Es urgente que implente un plan de revisión de políticas y procesos de utilización de equipos informáticos. La condición de su empresa es infraestructura sin control.
A35: =Title_ISBR7 -> 7. - Preparación para la recuperación ante desastres. | D35: =Score_ISBR7 -> #DIV/0!
A36: 3 < PO ≤ 4 | B36: Su empresa, aunque tiene administradas sus vulnerabilidades, sabe que pueden acontecer incidentes de seguridad y por eso mantiene un plan de recuperación de desatres actualizado y eficaz.
A37: 2 < PO ≤ 3 | B37: Su empresa debe extender la comunicación de recuperación de desastres a todo el personal y no solamente al especializado en informática. Es necesario que realice actividades de simulación de desastres para validar la eficacia de sus planes de recuperación.
A38: 1 < PO ≤ 2 | B38: Su empresa debe implementar un plan de recuperación de desastres. Su empresa ante un evento de desastre de seguridad de la información no está preparada y perderá tiempo valioso en organizar su reacción.
A39: 0 < PO ≤ 1 | B39: Su empresa está totalmente indefensa ante un desastre de seguridad de la información. Es urgente que implemente un plan para tal efecto.
A40: =Title_ISBR8 -> 8.- Los requisitos de seguridad de la información se integrarán en los procesos de ingeniería, adquisición y despliegue. | D40: =Score_ISBR8 -> #DIV/0!
...

Sheet CRITERIOS DE CALIFICACIÓN
B2: NO, EN ABSOLUTO. | C2: 0 | E2: 0-5%
B3: EN MENOR GRADO. | C3: 1 | E3: 6-35%
B4: HASTA CIERTO GRADO. | C4: 2 | E4: 36-65%
B5: EN GRAN PARTE. | C5: 3 | E5: 66-95%
B6: TOTALMENTE, COMPLETAMENTE. | C6: 4 | E6: 96-100%
B7: NO APLICABLE. | C7: N/A
B10: NO | C10: 0 | E10: 0
B11: SÍ | C11: 4 | E11: 1
